<?xml version="1.0" ?>
<robot name="farmbot" xmlns:xacro="http://www.ros.org/wiki/xacro">

<xacro:include filename="$(find farmbot_description)/urdf/materials.xacro" />
<!-- <xacro:include filename="$(find farmbot_description)/urdf/farmbot.trans" /> -->
<xacro:include filename="$(find farmbot_description)/urdf/farmbot.gazebo" />
<!-- <xacro:include filename="$(find farmbot_description)/urdf/gazebo_control.xacro" />  # Diff drive Controller  -->
<xacro:include filename="$(find farmbot_description)/urdf/gazebo_control_skid.xacro" />  <!-- Skid Steer Controller-->
<xacro:include filename="lidar.xacro" />
<!-- <xacro:include filename="$(find farmbot_description)/urdf/gazebo_control_acker.xacro" /> --> <!-- Ackermann Controller-->


<link name="base_link">
  <inertial>
    <origin xyz="0.14705284891472079 0.005827858553437189 3.5052699745628e-07" rpy="0 0 0"/>
    <mass value="8.113454311504578"/>
    <inertia ixx="0.03198" iyy="0.07641" izz="0.051754" ixy="-0.006565" iyz="-0.0" ixz="-1e-06"/>
  </inertial>
  <visual>
    <origin xyz="0 0 0.087" rpy="${pi/2} 0 0"/>
    <geometry>
      <mesh filename="file://$(find farmbot_description)/meshes/base_link.stl" scale="0.001 0.001 0.001"/>
    </geometry>
    <material name="silver"/>
  </visual>
  <collision>
    <origin xyz="0 0 0.087" rpy="${pi/2} 0 0"/>
    <geometry>
      <mesh filename="file://$(find farmbot_description)/meshes/base_link.stl" scale="0.001 0.001 0.001"/>
    </geometry>
  </collision>
</link>

<link name="component__1__1">
  <inertial>
    <origin xyz="-0.09236420727033787 0.00021362177608096554 -4.877897432420397e-07" rpy="0 0 0"/>
    <mass value="5.8958658025807615"/>
    <inertia ixx="0.022471" iyy="0.026114" izz="0.005817" ixy="-0.000116" iyz="-0.0" ixz="-0.0"/>
  </inertial>
  <visual>
    <origin xyz="0.0625 0.0 0.0" rpy="${pi/2} 0 0"/>
    <geometry>
      <mesh filename="file://$(find farmbot_description)/meshes/component__1__1.stl" scale="0.001 0.001 0.001"/>
    </geometry>
    <material name="silver"/>
  </visual>
  <collision>
    <origin xyz="0.0625 0.0 0.087" rpy="${pi/2} 0 0"/>
    <geometry>
      <mesh filename="file://$(find farmbot_description)/meshes/component__1__1.stl" scale="0.001 0.001 0.001"/>
    </geometry>
  </collision>
</link>

<link name="component__2__1">
  <inertial>
    <origin xyz="-3.7769361846407e-07 -3.5857001496231076e-07 -0.0059616689033889225" rpy="0 0 0"/>
    <mass value="20.82503572060766"/>
    <inertia ixx="0.063249" iyy="0.063249" izz="0.081111" ixy="-0.0" iyz="0.0" ixz="0.0"/>
  </inertial>
  <visual>
    <origin xyz="-0.161565 -0.166785 0.0" rpy="${pi/2} 0 0"/>
    <geometry>
      <mesh filename="file://$(find farmbot_description)/meshes/component__2__1.stl" scale="0.001 0.001 0.001"/>
    </geometry>
    <material name="silver"/>
  </visual>
  <collision>
    <origin xyz="-0.161565 -0.166785 0.0" rpy="${pi/2} 0 0"/>
    <geometry>
      <mesh filename="file://$(find farmbot_description)/meshes/component__2__1.stl" scale="0.001 0.001 0.001"/>
    </geometry>
  </collision>
</link>

<link name="component__2__2">
  <inertial>
    <origin xyz="-3.7769361846407e-07 -3.5857001489125644e-07 0.005961691828770682" rpy="0 0 0"/>
    <mass value="20.82503572060766"/>
    <inertia ixx="0.063249" iyy="0.063249" izz="0.081111" ixy="0.0" iyz="0.0" ixz="-0.0"/>
  </inertial>
  <visual>
    <origin xyz="-0.161565 0.166784 0.0" rpy="${pi/2} 0 0"/>
    <geometry>
      <mesh filename="file://$(find farmbot_description)/meshes/component__2__2.stl" scale="0.001 0.001 0.001"/>
    </geometry>
    <material name="silver"/>
  </visual>
  <collision>
    <origin xyz="-0.161565 0.166784 0.0" rpy="${pi/2} 0 0"/>
    <geometry>
      <mesh filename="file://$(find farmbot_description)/meshes/component__2__2.stl" scale="0.001 0.001 0.001"/>
    </geometry>
  </collision>
</link>

<link name="component__2__3">
  <inertial>
    <origin xyz="3.7769361843631444e-07 -3.5857001496231076e-07 -0.005961668903388867" rpy="0 0 0"/>
    <mass value="20.82503572060766"/>
    <inertia ixx="0.063249" iyy="0.063249" izz="0.081111" ixy="-0.0" iyz="0.0" ixz="-0.0"/>
  </inertial>
  <visual>
    <origin xyz="0.161565 -0.166785 0.0" rpy="${pi/2} 0 0"/>
    <geometry>
      <mesh filename="file://$(find farmbot_description)/meshes/component__2__3.stl" scale="0.001 0.001 0.001"/>
    </geometry>
    <material name="silver"/>
  </visual>
  <collision>
    <origin xyz="0.161565 -0.166785 0.0" rpy="${pi/2} 0 0"/>
    <geometry>
      <mesh filename="file://$(find farmbot_description)/meshes/component__2__3.stl" scale="0.001 0.001 0.001"/>
    </geometry>
  </collision>
</link>

<link name="component__2__4">
  <inertial>
    <origin xyz="3.7769361843631444e-07 -3.5857001489125644e-07 0.005961691828770765" rpy="0 0 0"/>
    <mass value="20.82503572060766"/>
    <inertia ixx="0.063249" iyy="0.063249" izz="0.081111" ixy="0.0" iyz="0.0" ixz="0.0"/>
  </inertial>
  <visual>
    <origin xyz="0.161565 0.166784 0.0" rpy="${pi/2} 0 0"/>
    <geometry>
      <mesh filename="file://$(find farmbot_description)/meshes/component__2__4.stl" scale="0.001 0.001 0.001"/>
    </geometry>
    <material name="silver"/>
  </visual>
  <collision>
    <origin xyz="0.161565 0.166784 0.0" rpy="${pi/2} 0 0"/>
    <geometry>
      <mesh filename="file://$(find farmbot_description)/meshes/component__2__4.stl" scale="0.001 0.001 0.001"/>
    </geometry>
  </collision>
</link>

<joint name="Revolute 1" type="fixed"> <!-- steering joint -->
  <origin xyz="-0.0625 0.0 0.087" rpy="0 0 0"/>
  <parent link="base_link"/>
  <child link="component__1__1"/>
  <axis xyz="0.0 0.0 1.0"/>
</joint>

<joint name="Revolute 2" type="continuous"> <!-- rear right wheel -->
  <origin xyz="0.161565 0.166785 0.087" rpy="0 0 0"/>
  <parent link="base_link"/>
  <child link="component__2__1"/>
  <axis xyz="-0.0 1.0 0.0"/>
</joint>

<joint name="Revolute 3" type="continuous"> <!-- rear left wheel -->
  <origin xyz="0.161565 -0.166784 0.087" rpy="0 0 0"/>
  <parent link="base_link"/>
  <child link="component__2__2"/>
  <axis xyz="-0.0 1.0 -0.0"/>
</joint>

<joint name="Revolute 4" type="continuous"> <!-- front right wheel -->
  <origin xyz="-0.161565 0.166785 0.087" rpy="0 0 0"/>
  <parent link="base_link"/>
  <child link="component__2__3"/>
  <axis xyz="0.0 1.0 -0.0"/>
</joint>

<joint name="Revolute 5" type="continuous"> <!-- front left wheel -->
  <origin xyz="-0.161565 -0.166784 0.087" rpy="0 0 0"/>
  <parent link="base_link"/>
  <child link="component__2__4"/>
  <axis xyz="0.0 1.0 0.0"/>
</joint>

</robot>
